<?xml version="1.0" ?>
<robot name="testbot">


  <link name="base"/>

  <joint name="fixed" type="fixed">
    <parent link="base"/>
    <child link="link1"/>
  </joint>

  <link name="link1">
    <collision>
      <origin xyz="0 0 0" rpy="1.570796 0 0"/>
      <geometry>
         <mesh filename="file:///home/hero_ws/src/testbot_description/urdf/gripper_body.DAE" scale="1 1 1"/>
      </geometry>
    </collision>
    <visual>
      <origin xyz="0 0 0" rpy="1.570796 0 0"/>
      <geometry>
        
        
        <mesh filename="file:///home/hero_ws/src/testbot_description/urdf/gripper_body.DAE" scale="1 1 1"/>
        
      </geometry>
    </visual>
    <inertial>
      <origin xyz="0 0 0.25" rpy="0 0 0"/>
      <mass value="1"/>
      <inertia ixx="1.0" ixy="0.0" ixz="0.0" iyy="1.0" iyz="0.0" izz="1.0"/>
    </inertial>
  </link>

  <joint name="joint1" type="revolute">
    <parent link="link1"/>
    <child link="link2"/>
    <origin xyz="0 0.02 0.074" rpy="0 0 0"/>
    <axis xyz="1 0 0"/>
    <limit effort="30" lower="-0.6" upper="0" velocity="1.571"/>
  </joint>

  <link name="link2">
    <collision>
      <origin xyz="0 0 0" rpy="1.570796 0 0"/>
      <geometry>
         <mesh filename="file:///home/hero_ws/src/testbot_description/urdf/gripper_left.DAE" scale="1 1 1"/>
      </geometry>
    </collision>
    <visual>
     <origin xyz="0 0 0" rpy="1.570796 0 0"/>
      <geometry>
         <mesh filename="file:///home/hero_ws/src/testbot_description/urdf/gripper_left.DAE" scale="1 1 1"/>
      </geometry>
    </visual>
    <inertial>
      <origin xyz="0 0 0.25" rpy="0 0 0"/>
      <mass value="1"/>
      <inertia ixx="1.0" ixy="0.0" ixz="0.0" iyy="1.0" iyz="0.0" izz="1.0"/>
    </inertial>
  </link>

  <joint name="joint2" type="revolute">
    <parent link="link1"/>
    <child link="link3"/>
    <origin xyz="0 -0.02 0.074" rpy="0 0 0"/>
    <axis xyz="1 0 0"/>
    <limit effort="30" lower="0" upper="0.6" velocity="1.571"/>
  </joint>

  <link name="link3">
    <collision>
     <origin xyz="0 0 0" rpy="1.570796 0 0"/>
      <geometry>
         <mesh filename="file:///home/hero_ws/src/testbot_description/urdf/gripper_right.DAE" scale="1 1 1"/>
      </geometry>
    </collision>
    <visual>
      <origin xyz="0 0 0" rpy="1.570796 0 0"/>
      <geometry>
         <mesh filename="file:///home/hero_ws/src/testbot_description/urdf/gripper_right.DAE" scale="1 1 1"/>
      </geometry>
    </visual>
    <inertial>
      <origin xyz="0 0 0.5" rpy="0 0 0"/>
      <mass value="1"/>
      <inertia ixx="1.0" ixy="0.0" ixz="0.0" iyy="1.0" iyz="0.0" izz="1.0"/>
    </inertial>
  </link>


</robot>
